<?xml version="1.0"?>
<sdf version="1.6">
  <world name="default">
    <include>
      <uri>model://ground_plane</uri>
    </include>
    <include>
      <uri>model://sun</uri>
    </include>

    <include>
      <uri>file:///home/sithija/mobile_receptionist_ws/src/gazebo_plugins/model/multifloor_building</uri>
      <!-- <pose>0 -2.94 0 0 0 0</pose> -->
      <pose>0 -2.90 0 0 0 0</pose>
    </include>

    <include>
      <uri>file:///home/sithija/mobile_receptionist_ws/src/gazebo_plugins/model/objects</uri>
      <!-- <pose>0 -2.94 0 0 0 0</pose> -->
      <pose>0 -2.90 0 0 0 0</pose>
    </include>

    <!-- Define the boxes and their joints -->
    <model name="sliding_boxes">
      <link name="level01_support">
        <pose>0 0 2.5 0 0 0</pose>
        <visual name="support01_visual">
          <geometry>
            <box>
              <size>3 0.1 0.95</size>
            </box>
          </geometry>
          <material>
            <script>
              <uri>file://media/materials/scripts/gazebo.material</uri>
              <name>Gazebo/White</name>
            </script>
          </material>
        </visual>
        <collision name="support01_collision">
          <geometry>
            <box>
              <size>3 0.1 0.95</size>
            </box>
          </geometry>
        </collision>
      </link>

      <link name="level02_support">
        <pose>0 0 5.5 0 0 0</pose>
        <visual name="support02_visual">
          <geometry>
            <box>
              <size>3 0.1 0.95</size>
            </box>
          </geometry>
          <material>
            <script>
              <uri>file://media/materials/scripts/gazebo.material</uri>
              <name>Gazebo/White</name>
            </script>
          </material>
        </visual>
        <collision name="support02_collision">
          <geometry>
            <box>
              <size>3 0.1 0.95</size>
            </box>
          </geometry>
        </collision>
      </link>

      <link name="level03_support">
        <pose>0 0 8.5 0 0 0</pose>
        <visual name="support03_visual">
          <geometry>
            <box>
              <size>3 0.1 0.95</size>
            </box>
          </geometry>
          <material>
            <script>
              <uri>file://media/materials/scripts/gazebo.material</uri>
              <name>Gazebo/White</name>
            </script>
          </material>
        </visual>
        <collision name="support03_collision">
          <geometry>
            <box>
              <size>3 0.1 0.95</size>
            </box>
          </geometry>
        </collision>
      </link>

      <link name="level04_support">
        <pose>0 0 11.5 0 0 0</pose>
        <visual name="support04_visual">
          <geometry>
            <box>
              <size>3 0.1 0.95</size>
            </box>
          </geometry>
          <material>
            <script>
              <uri>file://media/materials/scripts/gazebo.material</uri>
              <name>Gazebo/White</name>
            </script>
          </material>
        </visual>
        <collision name="support04_collision">
          <geometry>
            <box>
              <size>3 0.1 0.95</size>
            </box>
          </geometry>
        </collision>
      </link>

      <link name="front_wall_right">
        <pose>1.5 -0.05 6 0 0 0</pose>
        <visual name="front_wall_right_visual">
          <geometry>
            <box>
              <size>2 0.01 12</size>
            </box>
          </geometry>
          <material>
            <script>
              <uri>file://media/materials/scripts/gazebo.material</uri>
              <name>Gazebo/White</name>
            </script>
          </material>
        </visual>
        <collision name="front_wall_right_collision">
          <geometry>
            <box>
              <size>2 0.01 12</size>
            </box>
          </geometry>
        </collision>
      </link>

      <link name="front_wall_left">
        <pose>-1.5 -0.05 6 0 0 0</pose>
        <visual name="front_wall_left_visual">
          <geometry>
            <box>
              <size>2 0.01 12</size>
            </box>
          </geometry>
          <material>
            <script>
              <uri>file://media/materials/scripts/gazebo.material</uri>
              <name>Gazebo/White</name>
            </script>
          </material>
        </visual>
        <collision name="front_wall_left_collision">
          <geometry>
            <box>
              <size>2 0.01 12</size>
            </box>
          </geometry>
        </collision>
      </link>

      <link name="elevator_support_left">
        <gravity>false</gravity>
        <pose>-2.45 1.5 6 0 0 0</pose>
        <visual name="elevator_support_left_visual">
          <geometry>
            <box>
              <size>0.1 3 12</size>
            </box>
          </geometry>
          <material>
            <script>
              <uri>file://media/materials/scripts/gazebo.material</uri>
              <name>Gazebo/White</name>
            </script>
          </material>
        </visual>
        <collision name="elevator_support_left_collision">
          <geometry>
            <box>
              <size>0.1 3 12</size>
            </box>
          </geometry>
        </collision>
      </link>

      <!-- <link name="elevator_support_rail_front">
        <gravity>false</gravity>
        <pose>-2.45 0.30 0.015 0 0 0</pose>
        <visual name="elevator_support_rail_front_visual">
          <geometry>
            <box>
              <size>10 0.002 0.001</size>
            </box>
          </geometry>
          <material>
            <script>
              <uri>file://media/materials/scripts/gazebo.material</uri>
              <name>Gazebo/White</name>
            </script>
          </material>
        </visual>
        <collision name="elevator_support_rail_front_collision">
          <geometry>
            <box>
              <size>10 0.002 0.001</size>
            </box>
          </geometry>
        </collision>
      </link>

      <link name="elevator_support_rail_rear">
        <gravity>false</gravity>
        <pose>-2.45 1 0.015 0 0 0</pose>
        <visual name="elevator_support_rail_rear_visual">
          <geometry>
            <box>
              <size>10 0.002 0.001</size>
            </box>
          </geometry>
          <material>
            <script>
              <uri>file://media/materials/scripts/gazebo.material</uri>
              <name>Gazebo/White</name>
            </script>
          </material>
        </visual>
        <collision name="elevator_support_rail_rear_collision">
          <geometry>
            <box>
              <size>10 0.002 0.001</size>
            </box>
          </geometry>
        </collision>
      </link> -->

      <link name="base">
        <pose>0 0 0 0 0 0</pose>
      </link>


      <link name="elevator">
        <gravity>false</gravity>
        <visual name="elevator_visual">
          <geometry>
            <box>
              <size>5 3 0.03</size>
            </box>
          </geometry>
          <!-- <material>
            <script>
              <uri>file://media/materials/scripts/gazebo.material</uri>
              <name>Gazebo/Orange</name>
            </script>
          </material> -->
        </visual>
        <collision name="elevator_collision">
          <geometry>
            <box>
              <size>4.90 2.95 0.029</size>
            </box>
          </geometry>
          <surface>
            <friction>
              <ode>
                <mu>1000.0</mu>    <!-- Friction coefficient for lateral direction -->
                <mu2>1000.0</mu2>  <!-- Friction coefficient for second direction -->
              </ode>
            </friction>
        </surface>
        </collision>
        <pose>0.05 1.5 0 0 0 0</pose>
      </link>

      <link name="elevator_handle_right">
        <gravity>false</gravity>
        <visual name="elevator_handle_right_visual">
          <geometry>
            <box>
              <size>0.05 3 1.0</size>
            </box>
          </geometry>
          <material>
            <script>
              <uri>file://media/materials/scripts/gazebo.material</uri>
              <name>Gazebo/Orange</name>
            </script>
          </material>
        </visual>
        <collision name="elevator_handle_right_collision">
          <geometry>
            <box>
              <size>0.05 3 1.0</size>
            </box>
          </geometry>
        </collision>
        <pose>2.55 1.5 0.5 0 0 0</pose>
      </link>

      <link name="elevator_handle_rear">
        <gravity>false</gravity>
        <visual name="elevator_handle_rear_visual">
          <geometry>
            <box>
              <size>4.9 0.05 1.0</size>
            </box>
          </geometry>
          <material>
            <script>
              <uri>file://media/materials/scripts/gazebo.material</uri>
              <name>Gazebo/Orange</name>
            </script>
          </material>
        </visual>
        <collision name="elevator_handle_rear_collision">
          <geometry>
            <box>
              <size>0.05 3 1.0</size>
            </box>
          </geometry>
        </collision>
        <pose>0.1 3.0 0.5 0 0 0</pose>
      </link>

      <link name="box1">
        <visual name="box1_visual">
          <geometry>
            <box>
              <size>1 0.1 2</size>
            </box>
          </geometry>
          <material>
            <script>
              <uri>file://media/materials/scripts/gazebo.material</uri>
              <name>Gazebo/Orange</name>
            </script>
          </material>
        </visual>
        <collision name="box1_collision">
          <geometry>
            <box>
              <size>1 0.1 2</size>
            </box>
          </geometry>
        </collision>
        <pose>0 0 1 0 0 0</pose>
      </link>

      <link name="box2">
        <visual name="box2_visual">
          <geometry>
            <box>
              <size>1 0.1 2</size>
            </box>
          </geometry>
          <material>
            <script>
              <uri>file://media/materials/scripts/gazebo.material</uri>
              <name>Gazebo/Blue</name>
            </script>
          </material>
        </visual>
        <collision name="box2_collision">
          <geometry>
            <box>
              <size>1 0.1 2</size>
            </box>
          </geometry>
        </collision>
        <pose>0 0 4 0 0 0</pose>
      </link>

      <link name="box3">
        <visual name="box3_visual">
          <geometry>
            <box>
              <size>1 0.1 2</size>
            </box>
          </geometry>
          <material>
            <script>
              <uri>file://media/materials/scripts/gazebo.material</uri>
              <name>Gazebo/Green</name>
            </script>
          </material>
        </visual>
        <collision name="box3_collision">
          <geometry>
            <box>
              <size>1 0.1 2</size>
            </box>
          </geometry>
        </collision>
        <pose>0 0 7 0 0 0</pose>
      </link>

      <link name="box4">
        <visual name="box4_visual">
          <geometry>
            <box>
              <size>1 0.1 2</size>
            </box>
          </geometry>
          <material>
            <script>
              <uri>file://media/materials/scripts/gazebo.material</uri>
              <name>Gazebo/Red</name>
            </script>
          </material>
        </visual>
        <collision name="box4_collision">
          <geometry>
            <box>
              <size>1 0.1 2</size>
            </box>
          </geometry>
        </collision>
        <pose>0 0 10 0 0 0</pose>
      </link>

      <!-- <link name="ground_floor">
        <pose>0.0 -2 5 0 0</pose>
        <visual name="ground_floor_visual">
          <geometry>
            <box>
              <size>17 5 0.03</size>
            </box>
          </geometry>
        </visual>
        <collision name="ground_floor_collision">
          <geometry>
            <box>
              <size>17 5 0.03</size>
            </box>
          </geometry>
        </collision>
      </link>

      <joint name="ground_connector" type="fixed">
        <parent>base</parent>
        <child>ground_floor</child>
        <pose>0 0 0 0 0 0</pose>
      </joint> -->

      <link name="floor01_pannel_out">
        <visual name="floor01_pannel_out_visual">
          <geometry>
            <box>
              <size>0.1 0.01 0.5</size>
            </box>
          </geometry>
          <material>
          <script>
            <uri>file://media/materials/scripts/pannel01.material</uri>
            <name>Pannel01</name>
          </script>
          
          </material>
        </visual>
        <pose>0.60 -0.06 4 0 0 0</pose>
      </link>

      <joint name="floor01_pannel_out_joint" type="fixed">
        <parent>base</parent>
        <child>floor01_pannel_out</child>
        <pose>0 0 0 0 0 0</pose>
      </joint>

      <link name="floor02_pannel_out">
        <visual name="floor02_pannel_out_visual">
          <geometry>
            <box>
              <size>0.1 0.01 0.5</size>
            </box>
          </geometry>
          <material>
            <script>
              <uri>file://media/materials/scripts/gazebo.material</uri>
              <name>Gazebo/Orange</name>
            </script>
          </material>
        </visual>
        <pose>0.60 -0.06 7 0 0 0</pose>
      </link>

      <joint name="floor02_pannel_out_joint" type="fixed">
        <parent>base</parent>
        <child>floor02_pannel_out</child>
        <pose>0 0 0 0 0 0</pose>
      </joint>

      <link name="floor03_pannel_out">
        <visual name="floor03_pannel_out_visual">
          <geometry>
            <box>
              <size>0.1 0.01 0.5</size>
            </box>
          </geometry>
          <material>
            <script>
              <uri>file://media/materials/scripts/gazebo.material</uri>
              <name>Gazebo/Orange</name>
            </script>
          </material>
        </visual>
        <pose>0.60 -0.06 10 0 0 0</pose>
      </link>

      <joint name="floor03_pannel_out_joint" type="fixed">
        <parent>base</parent>
        <child>floor03_pannel_out</child>
        <pose>0 0 0 0 0 0</pose>
      </joint>

      <link name="floor01_pannel_in">
        <visual name="floor01_pannel_in_visual">
          <geometry>
            <box>
              <size>0.2 0.01 1.0</size>
            </box>
          </geometry>
          <material>
            <script>
              <uri>file://media/materials/scripts/gazebo.material</uri>
              <name>Gazebo/Orange</name>
            </script>
          </material>
        </visual>
        <pose>-0.70 -0.03 4 0 0 0</pose>
      </link>

      <joint name="floor01_pannel_in_joint" type="fixed">
        <parent>base</parent>
        <child>floor01_pannel_in</child>
        <pose>0 0 0 0 0 0</pose>
      </joint>

      <link name="floor02_pannel_in">
        <visual name="floor02_pannel_in_visual">
          <geometry>
            <box>
              <size>0.2 0.01 1.0</size>
            </box>
          </geometry>
          <material>
            <script>
              <uri>file://media/materials/scripts/gazebo.material</uri>
              <name>Gazebo/Orange</name>
            </script>
          </material>
        </visual>
        <pose>-0.70 -0.03 7 0 0 0</pose>
      </link>

      <joint name="floor02_pannel_in_joint" type="fixed">
        <parent>base</parent>
        <child>floor02_pannel_in</child>
        <pose>0 0 0 0 0 0</pose>
      </joint>

      <link name="floor03_pannel_in">
        <visual name="floor03_pannel_in_visual">
          <geometry>
            <box>
              <size>0.2 0.01 1.0</size>
            </box>
          </geometry>
          <material>
            <script>
              <uri>file://media/materials/scripts/gazebo.material</uri>
              <name>Gazebo/Orange</name>
            </script>
          </material>
        </visual>
        <pose>-0.70 -0.03 10 0 0 0</pose>
      </link>

      <joint name="floor03_pannel_in_joint" type="fixed">
        <parent>base</parent>
        <child>floor03_pannel_in</child>
        <pose>0 0 0 0 0 0</pose>
      </joint>

      <joint name="connector" type="fixed">
        <parent>base</parent>
        <child>Floor_6</child>
        <pose>0 0 0 0 0 0</pose>
      </joint>

      <joint name="joint_front_wall_left" type="fixed">
        <parent>level03_support</parent>
        <child>front_wall_left</child>
        <pose>0 0 0 0 0 0</pose>
      </joint>

      <joint name="joint_front_wall_right" type="fixed">
        <parent>level03_support</parent>
        <child>front_wall_right</child>
        <pose>0 0 0 0 0 0</pose>
      </joint>

      <joint name="joint_elevator_support_left" type="fixed">
        <parent>base</parent>
        <child>elevator_support_left</child>
        <pose>0 0 0 0 0 0</pose>
      </joint>

      <joint name="joint_elevator_handle_right" type="fixed">
        <parent>elevator</parent>
        <child>elevator_handle_right</child>
        <pose>0 0 0 0 0 0</pose>
      </joint>

      <joint name="joint_elevator_handle_rear" type="fixed">
        <parent>elevator</parent>
        <child>elevator_handle_rear</child>
        <pose>0 0 0 0 0 0</pose>
      </joint>

      <!-- <joint name="joint_elevator_rail_front" type="fixed">
        <parent>elevator</parent>
        <child>elevator_support_rail_front</child>
        <pose>0 0 0 0 0 0</pose>
      </joint>

      <joint name="joint_elevator_rail_rear" type="fixed">
        <parent>elevator</parent>
        <child>elevator_support_rail_rear</child>
        <pose>0 0 0 0 0 0</pose>
      </joint> -->

      <joint name="elevator_joint" type="prismatic">
        <parent>elevator_support_left</parent>
        <child>elevator</child>
        <pose>0 0 0 0 0 0</pose>
        <axis>
          <xyz>0 0 1</xyz>
          <limit>
            <lower>0</lower>
            <upper>13</upper>
            <effort>30000000000</effort>
            <velocity>100.0</velocity>
          </limit>
        </axis>
      </joint>
      <joint name="joint1" type="prismatic">
        <parent>base</parent>
        <child>box1</child>
        <pose>0 0 1 0 0 0</pose>
        <axis>
          <xyz>1 0 0</xyz>
          <limit>
            <lower>-0.5</lower>
            <!-- <lower>0</lower> -->
            <upper>1.5</upper>
            <effort>30</effort>
            <velocity>0.5</velocity>
          </limit>
        </axis>
      </joint>
      <joint name="joint2" type="prismatic">
        <parent>level01_support</parent>
        <child>box2</child>
        <pose>0 0 0 0 0 0</pose>
        <axis>
          <xyz>1 0 0</xyz>
          <limit>
            <lower>-0.5</lower>
            <!-- <lower>0</lower> -->
            <upper>1.5</upper>
            <effort>30</effort>
            <velocity>0.5</velocity>
          </limit>
        </axis>
      </joint>

      <joint name="joint3" type="prismatic">
        <parent>level02_support</parent>
        <child>box3</child>
        <pose>-0.5 0 0 0 0 0</pose>
        <axis>
          <xyz>1 0 0</xyz>
          <limit>
            <lower>-0.5</lower>
            <!-- <lower>0</lower> -->
            <upper>1.5</upper>
            <effort>30</effort>
            <velocity>0.5</velocity>
          </limit>
        </axis>
      </joint>

      <joint name="joint4" type="prismatic">
        <parent>level03_support</parent>
        <child>box4</child>
        <pose>0 0 0 0 0 0</pose>
        <axis>
          <xyz>1 0 0</xyz>
          <limit>
            <lower>-0.5</lower>
            <!-- <lower>0</lower> -->
            <upper>1.5</upper>
            <effort>30</effort>
            <velocity>0.5</velocity>
          </limit>
        </axis>
      </joint>

      <joint name="joint_level01_support" type="fixed">
        <parent>base</parent>
        <child>level01_support</child>
        <pose>0 0 4.1 0 0 0</pose>
      </joint>

      <joint name="joint_level02_support" type="fixed">
        <parent>base</parent>
        <child>level02_support</child>
        <pose>0 0 7.1 0 0 0</pose>
      </joint>
      <joint name="joint_level03_support" type="fixed">
        <parent>base</parent>
        <child>level03_support</child>
        <pose>0 0 10.1 0 0 0</pose>
      </joint>
       <joint name="joint_level04_support" type="fixed">
        <parent>base</parent>
        <child>level04_support</child>
        <pose>0 0 13.1 0 0 0</pose>
      </joint>

      <plugin name="multi_floor_door_control" filename="libmulti_floor_door_control.so"/>

    </model>

    <!-- Set the initial pose for the model -->
    <pose>0 0 0 0 0 0</pose>
  </world>
</sdf> 

//////////////////////////////////////////////////////////////////////////////////////////////////
